{
  "nbformat": 4,
  "nbformat_minor": 0,
  "metadata": {
    "kernelspec": {
      "display_name": "Python 3",
      "language": "python",
      "name": "python3"
    },
    "language_info": {
      "codemirror_mode": {
        "name": "ipython",
        "version": 3
      },
      "file_extension": ".py",
      "mimetype": "text/x-python",
      "name": "python",
      "nbconvert_exporter": "python",
      "pygments_lexer": "ipython3",
      "version": "3.7.3"
    },
    "colab": {
      "name": "09-errors-and-exceptions.ipynb",
      "provenance": []
    }
  },
  "cells": [
    {
      "cell_type": "code",
      "metadata": {
        "id": "HM_cyBY8WcMa",
        "colab_type": "code",
        "colab": {}
      },
      "source": [
        ""
      ],
      "execution_count": 0,
      "outputs": []
    },
    {
      "cell_type": "markdown",
      "metadata": {
        "id": "Ak1VE8SNYfk3",
        "colab_type": "text"
      },
      "source": [
        "# Errors and Exceptions\n",
        "Every programmer encounters errors, both those who are just beginning, and those who have been programming for years. Encountering errors and exceptions can be very frustrating at times, and can make coding feel like a hopeless endeavour. However, understanding what the different types of errors are and when you are likely to encounter them can help a lot. Once you know why you get certain types of errors, they become much easier to fix.\n",
        "\n",
        "Errors in Python have a very specific form, called a [traceback](https://swcarpentry.github.io/python-novice-inflammation/reference/#traceback). Let’s examine one:"
      ]
    },
    {
      "cell_type": "code",
      "metadata": {
        "id": "Zzmv-7A_ZS_q",
        "colab_type": "code",
        "colab": {
          "base_uri": "https://localhost:8080/",
          "height": 317
        },
        "outputId": "0a6b201d-c00c-48a1-c0a6-20c812f27372"
      },
      "source": [
        "# This code has an intentional error. You can type it directly or\n",
        "# use it for reference to understand the error message below.\n",
        "def favorite_ice_cream():\n",
        "    ice_creams = [\n",
        "        \"chocolate\",\n",
        "        \"vanilla\",\n",
        "        \"strawberry\"\n",
        "    ]\n",
        "    print(ice_creams[3])\n",
        "\n",
        "favorite_ice_cream()"
      ],
      "execution_count": 2,
      "outputs": [
        {
          "output_type": "error",
          "ename": "IndexError",
          "evalue": "ignored",
          "traceback": [
            "\u001b[0;31m---------------------------------------------------------------------------\u001b[0m",
            "\u001b[0;31mIndexError\u001b[0m                                Traceback (most recent call last)",
            "\u001b[0;32m<ipython-input-2-d9c4f1bc4564>\u001b[0m in \u001b[0;36m<module>\u001b[0;34m()\u001b[0m\n\u001b[1;32m      9\u001b[0m     \u001b[0mprint\u001b[0m\u001b[0;34m(\u001b[0m\u001b[0mice_creams\u001b[0m\u001b[0;34m[\u001b[0m\u001b[0;36m3\u001b[0m\u001b[0;34m]\u001b[0m\u001b[0;34m)\u001b[0m\u001b[0;34m\u001b[0m\u001b[0;34m\u001b[0m\u001b[0m\n\u001b[1;32m     10\u001b[0m \u001b[0;34m\u001b[0m\u001b[0m\n\u001b[0;32m---> 11\u001b[0;31m \u001b[0mfavorite_ice_cream\u001b[0m\u001b[0;34m(\u001b[0m\u001b[0;34m)\u001b[0m\u001b[0;34m\u001b[0m\u001b[0;34m\u001b[0m\u001b[0m\n\u001b[0m",
            "\u001b[0;32m<ipython-input-2-d9c4f1bc4564>\u001b[0m in \u001b[0;36mfavorite_ice_cream\u001b[0;34m()\u001b[0m\n\u001b[1;32m      7\u001b[0m         \u001b[0;34m\"strawberry\"\u001b[0m\u001b[0;34m\u001b[0m\u001b[0;34m\u001b[0m\u001b[0m\n\u001b[1;32m      8\u001b[0m     ]\n\u001b[0;32m----> 9\u001b[0;31m     \u001b[0mprint\u001b[0m\u001b[0;34m(\u001b[0m\u001b[0mice_creams\u001b[0m\u001b[0;34m[\u001b[0m\u001b[0;36m3\u001b[0m\u001b[0;34m]\u001b[0m\u001b[0;34m)\u001b[0m\u001b[0;34m\u001b[0m\u001b[0;34m\u001b[0m\u001b[0m\n\u001b[0m\u001b[1;32m     10\u001b[0m \u001b[0;34m\u001b[0m\u001b[0m\n\u001b[1;32m     11\u001b[0m \u001b[0mfavorite_ice_cream\u001b[0m\u001b[0;34m(\u001b[0m\u001b[0;34m)\u001b[0m\u001b[0;34m\u001b[0m\u001b[0;34m\u001b[0m\u001b[0m\n",
            "\u001b[0;31mIndexError\u001b[0m: list index out of range"
          ]
        }
      ]
    },
    {
      "cell_type": "markdown",
      "metadata": {
        "id": "tXws1akiZZ2E",
        "colab_type": "text"
      },
      "source": [
        "This particular traceback has two levels. You can determine the number of levels by looking for the number of arrows on the left hand side. In this case:\n",
        "\n",
        "The first shows code from the cell above, with an arrow pointing to Line 8 (which is favorite_ice_cream()).\n",
        "\n",
        "The second shows some code in the function favorite_ice_cream, with an arrow pointing to Line 6 (which is print(ice_creams[3])).\n",
        "\n",
        "The last level is the actual place where the error occurred. The other level(s) show what function the program executed to get to the next level down. So, in this case, the program first performed a [function](https://swcarpentry.github.io/python-novice-inflammation/reference/#function-call) call to the function favorite_ice_cream. Inside this function, the program encountered an error on Line 6, when it tried to run the code print(ice_creams[3])."
      ]
    },
    {
      "cell_type": "markdown",
      "metadata": {
        "id": "vSnJI-GUncjS",
        "colab_type": "text"
      },
      "source": [
        "### Long Tracebacks (side note)\n",
        "\n",
        "---\n",
        "\n",
        "\n",
        "Sometimes, you might see a traceback that is very long – sometimes they might even be 20 levels deep! This can make it seem like something horrible happened, but the length of the error message does not reflect severity, rather, it indicates that your program called many functions before it encountered the error. Most of the time, the actual place where the error occurred is at the bottom-most level, so you can skip down the traceback to the bottom.\n",
        "\n",
        "\n",
        "---\n",
        "\n"
      ]
    },
    {
      "cell_type": "markdown",
      "metadata": {
        "id": "eF4PpEuEnp72",
        "colab_type": "text"
      },
      "source": [
        "So what error did the program actually encounter? In the last line of the traceback, Python helpfully tells us the category or type of error (in this case, it is an IndexError) and a more detailed error message (in this case, it says “list index out of range”).\n",
        "\n",
        "If you encounter an error and don’t know what it means, it is still important to read the traceback closely. That way, if you fix the error, but encounter a new one, you can tell that the error changed. Additionally, sometimes knowing where the error occurred is enough to fix it, even if you don’t entirely understand the message.\n",
        "\n",
        "If you do encounter an error you don’t recognize, try looking at the [official documentation on errors.](https://docs.python.org/3/library/exceptions.html) However, note that you may not always be able to find the error there, as it is possible to create custom errors. In that case, hopefully the custom error message is informative enough to help you figure out what went wrong."
      ]
    },
    {
      "cell_type": "markdown",
      "metadata": {
        "id": "-Y56QlXuoInN",
        "colab_type": "text"
      },
      "source": [
        "## Syntax Errors\n",
        "When you forget a colon at the end of a line, accidentally add one space too many when indenting under an if statement, or forget a parenthesis, you will encounter a [syntax error](https://swcarpentry.github.io/python-novice-inflammation/reference/#syntax-error). This means that Python couldn’t figure out how to read your program. This is similar to forgetting punctuation in English: for example, this text is difficult to read there is no punctuation there is also no capitalization why is this hard because you have to figure out where each sentence ends you also have to figure out where each sentence begins to some extent it might be ambiguous if there should be a sentence break or not\n",
        "\n",
        "People can typically figure out what is meant by text with no punctuation, but people are much smarter than computers. If Python doesn’t know how to read the program, it will give up and inform you with an error. For example:"
      ]
    },
    {
      "cell_type": "code",
      "metadata": {
        "id": "dV98_9YUnoyS",
        "colab_type": "code",
        "colab": {
          "base_uri": "https://localhost:8080/",
          "height": 130
        },
        "outputId": "4e9f1539-f5aa-414c-9e05-d42669aba0dd"
      },
      "source": [
        "def some_function()\n",
        "    msg = \"hello, world!\"\n",
        "    print(msg)\n",
        "     return msg"
      ],
      "execution_count": 3,
      "outputs": [
        {
          "output_type": "error",
          "ename": "SyntaxError",
          "evalue": "ignored",
          "traceback": [
            "\u001b[0;36m  File \u001b[0;32m\"<ipython-input-3-95d391d879b2>\"\u001b[0;36m, line \u001b[0;32m1\u001b[0m\n\u001b[0;31m    def some_function()\u001b[0m\n\u001b[0m                       ^\u001b[0m\n\u001b[0;31mSyntaxError\u001b[0m\u001b[0;31m:\u001b[0m invalid syntax\n"
          ]
        }
      ]
    },
    {
      "cell_type": "markdown",
      "metadata": {
        "id": "Ro7735nuojdg",
        "colab_type": "text"
      },
      "source": [
        "Here, Python tells us that there is a [SyntaxError](https://swcarpentry.github.io/python-novice-inflammation/reference/#syntax-error) on line 1, and even puts a little arrow in the place where there is an issue. In this case the problem is that the function definition is missing a colon at the end.\n",
        "\n",
        "Actually, the function above has two issues with syntax. If we fix the problem with the colon, we see that there is also an IndentationError, which means that the lines in the function definition do not all have the same indentation:"
      ]
    },
    {
      "cell_type": "code",
      "metadata": {
        "id": "kXxEL_Qkoe7V",
        "colab_type": "code",
        "colab": {
          "base_uri": "https://localhost:8080/",
          "height": 130
        },
        "outputId": "b1c3db92-fe12-4ceb-8699-3d9967db8346"
      },
      "source": [
        "def some_function():\n",
        "    msg = \"hello, world!\"\n",
        "    print(msg)\n",
        "     return msg"
      ],
      "execution_count": 4,
      "outputs": [
        {
          "output_type": "error",
          "ename": "IndentationError",
          "evalue": "ignored",
          "traceback": [
            "\u001b[0;36m  File \u001b[0;32m\"<ipython-input-4-18d6e2304f63>\"\u001b[0;36m, line \u001b[0;32m4\u001b[0m\n\u001b[0;31m    return msg\u001b[0m\n\u001b[0m    ^\u001b[0m\n\u001b[0;31mIndentationError\u001b[0m\u001b[0;31m:\u001b[0m unexpected indent\n"
          ]
        }
      ]
    },
    {
      "cell_type": "markdown",
      "metadata": {
        "id": "kl5aGDX9orzr",
        "colab_type": "text"
      },
      "source": [
        "Both SyntaxError and IndentationError indicate a problem with the syntax of your program, but an IndentationError is more specific: it always means that there is a problem with how your code is indented."
      ]
    },
    {
      "cell_type": "markdown",
      "metadata": {
        "id": "miVM1qNIoyKy",
        "colab_type": "text"
      },
      "source": [
        "### Tabs and Spaces (side note)\n",
        "\n",
        "\n",
        "---\n",
        "Some indentation errors are harder to spot than others. In particular, mixing spaces and tabs can be difficult to spot because they are both [whitespace](https://swcarpentry.github.io/python-novice-inflammation/reference/#whitespace). In the example below, the first two lines in the body of the function some_function are indented with tabs, while the third line — with spaces. If you’re working in a Jupyter notebook, be sure to copy and paste this example rather than trying to type it in manually because Jupyter automatically replaces tabs with spaces.\n",
        "\n",
        "\n",
        "---\n",
        "\n",
        "\n"
      ]
    },
    {
      "cell_type": "code",
      "metadata": {
        "id": "f6_bvzHMoqxA",
        "colab_type": "code",
        "colab": {
          "base_uri": "https://localhost:8080/",
          "height": 130
        },
        "outputId": "28b37368-215a-49c2-b83a-ee1e00b26c62"
      },
      "source": [
        "def some_function():\n",
        "\tmsg = \"hello, world!\"\n",
        "\tprint(msg)\n",
        "        return msg\n",
        "\n",
        "# Visually it is impossible to spot the error. Fortunately, Python does not allow you to mix tabs and spaces."
      ],
      "execution_count": 6,
      "outputs": [
        {
          "output_type": "error",
          "ename": "TabError",
          "evalue": "ignored",
          "traceback": [
            "\u001b[0;36m  File \u001b[0;32m\"<ipython-input-6-d653b5a6cf4a>\"\u001b[0;36m, line \u001b[0;32m4\u001b[0m\n\u001b[0;31m    return msg\u001b[0m\n\u001b[0m              ^\u001b[0m\n\u001b[0;31mTabError\u001b[0m\u001b[0;31m:\u001b[0m inconsistent use of tabs and spaces in indentation\n"
          ]
        }
      ]
    },
    {
      "cell_type": "markdown",
      "metadata": {
        "id": "_KrQbBsLpay1",
        "colab_type": "text"
      },
      "source": [
        "## Variable Name Errors\n",
        "Another very common type of error is called a NameError, and occurs when you try to use a variable that does not exist. For example:"
      ]
    },
    {
      "cell_type": "code",
      "metadata": {
        "id": "AuK-IcErpPOf",
        "colab_type": "code",
        "colab": {
          "base_uri": "https://localhost:8080/",
          "height": 164
        },
        "outputId": "f3e95a23-fea7-4bac-da41-db7d2995e480"
      },
      "source": [
        "print(a)"
      ],
      "execution_count": 7,
      "outputs": [
        {
          "output_type": "error",
          "ename": "NameError",
          "evalue": "ignored",
          "traceback": [
            "\u001b[0;31m---------------------------------------------------------------------------\u001b[0m",
            "\u001b[0;31mNameError\u001b[0m                                 Traceback (most recent call last)",
            "\u001b[0;32m<ipython-input-7-bca0e2660b9f>\u001b[0m in \u001b[0;36m<module>\u001b[0;34m()\u001b[0m\n\u001b[0;32m----> 1\u001b[0;31m \u001b[0mprint\u001b[0m\u001b[0;34m(\u001b[0m\u001b[0ma\u001b[0m\u001b[0;34m)\u001b[0m\u001b[0;34m\u001b[0m\u001b[0;34m\u001b[0m\u001b[0m\n\u001b[0m",
            "\u001b[0;31mNameError\u001b[0m: name 'a' is not defined"
          ]
        }
      ]
    },
    {
      "cell_type": "markdown",
      "metadata": {
        "id": "hVezBrkPpkeW",
        "colab_type": "text"
      },
      "source": [
        "Variable name errors come with some of the most informative error messages, which are usually of the form “name ‘the_variable_name’ is not defined”.\n",
        "\n",
        "Why does this error message occur? That’s a harder question to answer, because it depends on what your code is supposed to do. However, there are a few very common reasons why you might have an undefined variable. The first is that you meant to use a [string](https://swcarpentry.github.io/python-novice-inflammation/reference/#string), but forgot to put quotes around it:"
      ]
    },
    {
      "cell_type": "code",
      "metadata": {
        "id": "VU1WMHOlphdC",
        "colab_type": "code",
        "colab": {
          "base_uri": "https://localhost:8080/",
          "height": 164
        },
        "outputId": "8604e66e-05ca-499e-f6d8-26c2c7c936cb"
      },
      "source": [
        "print(hello)"
      ],
      "execution_count": 8,
      "outputs": [
        {
          "output_type": "error",
          "ename": "NameError",
          "evalue": "ignored",
          "traceback": [
            "\u001b[0;31m---------------------------------------------------------------------------\u001b[0m",
            "\u001b[0;31mNameError\u001b[0m                                 Traceback (most recent call last)",
            "\u001b[0;32m<ipython-input-8-1cd80308eb4c>\u001b[0m in \u001b[0;36m<module>\u001b[0;34m()\u001b[0m\n\u001b[0;32m----> 1\u001b[0;31m \u001b[0mprint\u001b[0m\u001b[0;34m(\u001b[0m\u001b[0mhello\u001b[0m\u001b[0;34m)\u001b[0m\u001b[0;34m\u001b[0m\u001b[0;34m\u001b[0m\u001b[0m\n\u001b[0m",
            "\u001b[0;31mNameError\u001b[0m: name 'hello' is not defined"
          ]
        }
      ]
    },
    {
      "cell_type": "markdown",
      "metadata": {
        "id": "LsGeOzAfp0GG",
        "colab_type": "text"
      },
      "source": [
        "The second reason is that you might be trying to use a variable that does not yet exist. In the following example, count should have been defined (e.g., with count = 0) before the for loop:"
      ]
    },
    {
      "cell_type": "code",
      "metadata": {
        "id": "h4WR6zu_pxKo",
        "colab_type": "code",
        "colab": {
          "base_uri": "https://localhost:8080/",
          "height": 198
        },
        "outputId": "cd5db91f-7548-4fdd-c269-0697778ceda1"
      },
      "source": [
        "for number in range(10):\n",
        "    count = count + number\n",
        "print(\"The count is:\", count)"
      ],
      "execution_count": 9,
      "outputs": [
        {
          "output_type": "error",
          "ename": "NameError",
          "evalue": "ignored",
          "traceback": [
            "\u001b[0;31m---------------------------------------------------------------------------\u001b[0m",
            "\u001b[0;31mNameError\u001b[0m                                 Traceback (most recent call last)",
            "\u001b[0;32m<ipython-input-9-223ed4c94391>\u001b[0m in \u001b[0;36m<module>\u001b[0;34m()\u001b[0m\n\u001b[1;32m      1\u001b[0m \u001b[0;32mfor\u001b[0m \u001b[0mnumber\u001b[0m \u001b[0;32min\u001b[0m \u001b[0mrange\u001b[0m\u001b[0;34m(\u001b[0m\u001b[0;36m10\u001b[0m\u001b[0;34m)\u001b[0m\u001b[0;34m:\u001b[0m\u001b[0;34m\u001b[0m\u001b[0;34m\u001b[0m\u001b[0m\n\u001b[0;32m----> 2\u001b[0;31m     \u001b[0mcount\u001b[0m \u001b[0;34m=\u001b[0m \u001b[0mcount\u001b[0m \u001b[0;34m+\u001b[0m \u001b[0mnumber\u001b[0m\u001b[0;34m\u001b[0m\u001b[0;34m\u001b[0m\u001b[0m\n\u001b[0m\u001b[1;32m      3\u001b[0m \u001b[0mprint\u001b[0m\u001b[0;34m(\u001b[0m\u001b[0;34m\"The count is:\"\u001b[0m\u001b[0;34m,\u001b[0m \u001b[0mcount\u001b[0m\u001b[0;34m)\u001b[0m\u001b[0;34m\u001b[0m\u001b[0;34m\u001b[0m\u001b[0m\n",
            "\u001b[0;31mNameError\u001b[0m: name 'count' is not defined"
          ]
        }
      ]
    },
    {
      "cell_type": "markdown",
      "metadata": {
        "id": "amM0GoYYp77o",
        "colab_type": "text"
      },
      "source": [
        "Finally, the third possibility is that you made a typo when you were writing your code. Let’s say we fixed the error above by adding the line Count = 0 before the for loop. Frustratingly, this actually does not fix the error. Remember that variables are [case-sensitive](https://swcarpentry.github.io/python-novice-inflammation/reference/#case-sensitive), so the variable count is different from Count. We still get the same error, because we still have not defined count:"
      ]
    },
    {
      "cell_type": "code",
      "metadata": {
        "id": "PwLPgixop2h9",
        "colab_type": "code",
        "colab": {
          "base_uri": "https://localhost:8080/",
          "height": 215
        },
        "outputId": "ed4c92a7-eb30-4b3d-f586-4f30f30059bd"
      },
      "source": [
        "Count = 0\n",
        "for number in range(10):\n",
        "    count = count + number\n",
        "print(\"The count is:\", count)"
      ],
      "execution_count": 10,
      "outputs": [
        {
          "output_type": "error",
          "ename": "NameError",
          "evalue": "ignored",
          "traceback": [
            "\u001b[0;31m---------------------------------------------------------------------------\u001b[0m",
            "\u001b[0;31mNameError\u001b[0m                                 Traceback (most recent call last)",
            "\u001b[0;32m<ipython-input-10-52704ad2ac41>\u001b[0m in \u001b[0;36m<module>\u001b[0;34m()\u001b[0m\n\u001b[1;32m      1\u001b[0m \u001b[0mCount\u001b[0m \u001b[0;34m=\u001b[0m \u001b[0;36m0\u001b[0m\u001b[0;34m\u001b[0m\u001b[0;34m\u001b[0m\u001b[0m\n\u001b[1;32m      2\u001b[0m \u001b[0;32mfor\u001b[0m \u001b[0mnumber\u001b[0m \u001b[0;32min\u001b[0m \u001b[0mrange\u001b[0m\u001b[0;34m(\u001b[0m\u001b[0;36m10\u001b[0m\u001b[0;34m)\u001b[0m\u001b[0;34m:\u001b[0m\u001b[0;34m\u001b[0m\u001b[0;34m\u001b[0m\u001b[0m\n\u001b[0;32m----> 3\u001b[0;31m     \u001b[0mcount\u001b[0m \u001b[0;34m=\u001b[0m \u001b[0mcount\u001b[0m \u001b[0;34m+\u001b[0m \u001b[0mnumber\u001b[0m\u001b[0;34m\u001b[0m\u001b[0;34m\u001b[0m\u001b[0m\n\u001b[0m\u001b[1;32m      4\u001b[0m \u001b[0mprint\u001b[0m\u001b[0;34m(\u001b[0m\u001b[0;34m\"The count is:\"\u001b[0m\u001b[0;34m,\u001b[0m \u001b[0mcount\u001b[0m\u001b[0;34m)\u001b[0m\u001b[0;34m\u001b[0m\u001b[0;34m\u001b[0m\u001b[0m\n",
            "\u001b[0;31mNameError\u001b[0m: name 'count' is not defined"
          ]
        }
      ]
    },
    {
      "cell_type": "markdown",
      "metadata": {
        "id": "TSDox2wpqJ-B",
        "colab_type": "text"
      },
      "source": [
        "## Index Errors\n",
        "Next up are errors having to do with containers (like lists and strings) and the items within them. If you try to access an item in a list or a string that does not exist, then you will get an error. This makes sense: if you asked someone what day they would like to get coffee, and they answered “caturday”, you might be a bit annoyed. Python gets similarly annoyed if you try to ask it for an item that doesn’t exist:"
      ]
    },
    {
      "cell_type": "code",
      "metadata": {
        "id": "yEUrFEtQqEpV",
        "colab_type": "code",
        "colab": {
          "base_uri": "https://localhost:8080/",
          "height": 249
        },
        "outputId": "9c2a4a63-ebd7-4faa-8a17-68492b4f771f"
      },
      "source": [
        "letters = ['a', 'b', 'c']\n",
        "print(\"Letter #1 is\", letters[0])\n",
        "print(\"Letter #2 is\", letters[1])\n",
        "print(\"Letter #3 is\", letters[2])\n",
        "print(\"Letter #4 is\", letters[3])"
      ],
      "execution_count": 11,
      "outputs": [
        {
          "output_type": "stream",
          "text": [
            "Letter #1 is a\n",
            "Letter #2 is b\n",
            "Letter #3 is c\n"
          ],
          "name": "stdout"
        },
        {
          "output_type": "error",
          "ename": "IndexError",
          "evalue": "ignored",
          "traceback": [
            "\u001b[0;31m---------------------------------------------------------------------------\u001b[0m",
            "\u001b[0;31mIndexError\u001b[0m                                Traceback (most recent call last)",
            "\u001b[0;32m<ipython-input-11-9624ce6f7f87>\u001b[0m in \u001b[0;36m<module>\u001b[0;34m()\u001b[0m\n\u001b[1;32m      3\u001b[0m \u001b[0mprint\u001b[0m\u001b[0;34m(\u001b[0m\u001b[0;34m\"Letter #2 is\"\u001b[0m\u001b[0;34m,\u001b[0m \u001b[0mletters\u001b[0m\u001b[0;34m[\u001b[0m\u001b[0;36m1\u001b[0m\u001b[0;34m]\u001b[0m\u001b[0;34m)\u001b[0m\u001b[0;34m\u001b[0m\u001b[0;34m\u001b[0m\u001b[0m\n\u001b[1;32m      4\u001b[0m \u001b[0mprint\u001b[0m\u001b[0;34m(\u001b[0m\u001b[0;34m\"Letter #3 is\"\u001b[0m\u001b[0;34m,\u001b[0m \u001b[0mletters\u001b[0m\u001b[0;34m[\u001b[0m\u001b[0;36m2\u001b[0m\u001b[0;34m]\u001b[0m\u001b[0;34m)\u001b[0m\u001b[0;34m\u001b[0m\u001b[0;34m\u001b[0m\u001b[0m\n\u001b[0;32m----> 5\u001b[0;31m \u001b[0mprint\u001b[0m\u001b[0;34m(\u001b[0m\u001b[0;34m\"Letter #4 is\"\u001b[0m\u001b[0;34m,\u001b[0m \u001b[0mletters\u001b[0m\u001b[0;34m[\u001b[0m\u001b[0;36m3\u001b[0m\u001b[0;34m]\u001b[0m\u001b[0;34m)\u001b[0m\u001b[0;34m\u001b[0m\u001b[0;34m\u001b[0m\u001b[0m\n\u001b[0m",
            "\u001b[0;31mIndexError\u001b[0m: list index out of range"
          ]
        }
      ]
    },
    {
      "cell_type": "markdown",
      "metadata": {
        "id": "2wJYxmBRqXnV",
        "colab_type": "text"
      },
      "source": [
        "Here, Python is telling us that there is an IndexError in our code, meaning we tried to access a list index that did not exist."
      ]
    },
    {
      "cell_type": "markdown",
      "metadata": {
        "id": "lMiiXQWiqgb_",
        "colab_type": "text"
      },
      "source": [
        "## File Errors\n",
        "The last type of error we’ll cover today are those associated with reading and writing files: FileNotFoundError. If you try to read a file that does not exist, you will receive a FileNotFoundError telling you so. If you attempt to write to a file that was opened read-only, Python 3 returns an UnsupportedOperationError. More generally, problems with input and output manifest as IOErrors or OSErrors, depending on the version of Python you use."
      ]
    },
    {
      "cell_type": "code",
      "metadata": {
        "id": "TlMMkfzUqPZu",
        "colab_type": "code",
        "colab": {
          "base_uri": "https://localhost:8080/",
          "height": 164
        },
        "outputId": "73560526-9217-4dcd-c383-a02060c0fedc"
      },
      "source": [
        "file_handle = open('myfile.txt', 'r')"
      ],
      "execution_count": 12,
      "outputs": [
        {
          "output_type": "error",
          "ename": "FileNotFoundError",
          "evalue": "ignored",
          "traceback": [
            "\u001b[0;31m---------------------------------------------------------------------------\u001b[0m",
            "\u001b[0;31mFileNotFoundError\u001b[0m                         Traceback (most recent call last)",
            "\u001b[0;32m<ipython-input-12-080b0e91cc46>\u001b[0m in \u001b[0;36m<module>\u001b[0;34m()\u001b[0m\n\u001b[0;32m----> 1\u001b[0;31m \u001b[0mfile_handle\u001b[0m \u001b[0;34m=\u001b[0m \u001b[0mopen\u001b[0m\u001b[0;34m(\u001b[0m\u001b[0;34m'myfile.txt'\u001b[0m\u001b[0;34m,\u001b[0m \u001b[0;34m'r'\u001b[0m\u001b[0;34m)\u001b[0m\u001b[0;34m\u001b[0m\u001b[0;34m\u001b[0m\u001b[0m\n\u001b[0m",
            "\u001b[0;31mFileNotFoundError\u001b[0m: [Errno 2] No such file or directory: 'myfile.txt'"
          ]
        }
      ]
    },
    {
      "cell_type": "markdown",
      "metadata": {
        "id": "OsHEWK4Fqsos",
        "colab_type": "text"
      },
      "source": [
        "One reason for receiving this error is that you specified an incorrect path to the file. For example, if I am currently in a folder called myproject, and I have a file in myproject/writing/myfile.txt, but I try to open myfile.txt, this will fail. The correct path would be writing/myfile.txt. It is also possible that the file name or its path contains a typo.\n",
        "\n",
        "A related issue can occur if you use the “read” flag instead of the “write” flag. Python will not give you an error if you try to open a file for writing when the file does not exist. However, if you meant to open a file for reading, but accidentally opened it for writing, and then try to read from it, you will get an UnsupportedOperation error telling you that the file was not opened for reading:"
      ]
    },
    {
      "cell_type": "code",
      "metadata": {
        "id": "jKYg9XuKr2KJ",
        "colab_type": "code",
        "colab": {
          "base_uri": "https://localhost:8080/",
          "height": 181
        },
        "outputId": "ae38e655-e3f7-4058-a7c9-1eb7c126a17a"
      },
      "source": [
        "file_handle = open('myfile.txt', 'w')\n",
        "file_handle.read()"
      ],
      "execution_count": 13,
      "outputs": [
        {
          "output_type": "error",
          "ename": "UnsupportedOperation",
          "evalue": "ignored",
          "traceback": [
            "\u001b[0;31m---------------------------------------------------------------------------\u001b[0m",
            "\u001b[0;31mUnsupportedOperation\u001b[0m                      Traceback (most recent call last)",
            "\u001b[0;32m<ipython-input-13-063a9999adc0>\u001b[0m in \u001b[0;36m<module>\u001b[0;34m()\u001b[0m\n\u001b[1;32m      1\u001b[0m \u001b[0mfile_handle\u001b[0m \u001b[0;34m=\u001b[0m \u001b[0mopen\u001b[0m\u001b[0;34m(\u001b[0m\u001b[0;34m'myfile.txt'\u001b[0m\u001b[0;34m,\u001b[0m \u001b[0;34m'w'\u001b[0m\u001b[0;34m)\u001b[0m\u001b[0;34m\u001b[0m\u001b[0;34m\u001b[0m\u001b[0m\n\u001b[0;32m----> 2\u001b[0;31m \u001b[0mfile_handle\u001b[0m\u001b[0;34m.\u001b[0m\u001b[0mread\u001b[0m\u001b[0;34m(\u001b[0m\u001b[0;34m)\u001b[0m\u001b[0;34m\u001b[0m\u001b[0;34m\u001b[0m\u001b[0m\n\u001b[0m",
            "\u001b[0;31mUnsupportedOperation\u001b[0m: not readable"
          ]
        }
      ]
    },
    {
      "cell_type": "markdown",
      "metadata": {
        "id": "TabSJFCdr5cR",
        "colab_type": "text"
      },
      "source": [
        "These are the most common errors with files, though many others exist. If you get an error that you’ve never seen before, searching the Internet for that error type often reveals common reasons why you might get that error."
      ]
    },
    {
      "cell_type": "markdown",
      "metadata": {
        "id": "4KRFf57wr-We",
        "colab_type": "text"
      },
      "source": [
        "### Reading Error Messages (side note)\n",
        "\n",
        "\n",
        "---\n",
        "Read the Python code and the resulting traceback below, and answer the following questions:\n",
        "\n",
        "How many levels does the traceback have?\n",
        "\n",
        "What is the function name where the error occurred?\n",
        "\n",
        "On which line number in this function did the error occur?\n",
        "\n",
        "What is the type of error?\n",
        "\n",
        "What is the error message?\n",
        "\n",
        "\n",
        "---\n",
        "\n"
      ]
    },
    {
      "cell_type": "code",
      "metadata": {
        "id": "pOV7vknqr4XU",
        "colab_type": "code",
        "colab": {
          "base_uri": "https://localhost:8080/",
          "height": 341
        },
        "outputId": "049ced68-1073-4402-fa55-0458d1e05727"
      },
      "source": [
        "# This code has an intentional error. Do not type it directly;\n",
        "# use it for reference to understand the error message below.\n",
        "def print_message(day):\n",
        "    messages = {\n",
        "        \"monday\": \"Hello, world!\",\n",
        "        \"tuesday\": \"Today is Tuesday!\",\n",
        "        \"wednesday\": \"It is the middle of the week.\",\n",
        "        \"thursday\": \"Today is Donnerstag in German!\",\n",
        "        \"friday\": \"Last day of the week!\",\n",
        "        \"saturday\": \"Hooray for the weekend!\",\n",
        "        \"sunday\": \"Aw, the weekend is almost over.\"\n",
        "    }\n",
        "    print(messages[day])\n",
        "\n",
        "def print_friday_message():\n",
        "    print_message(\"Friday\")\n",
        "\n",
        "print_friday_message()"
      ],
      "execution_count": 14,
      "outputs": [
        {
          "output_type": "error",
          "ename": "KeyError",
          "evalue": "ignored",
          "traceback": [
            "\u001b[0;31m---------------------------------------------------------------------------\u001b[0m",
            "\u001b[0;31mKeyError\u001b[0m                                  Traceback (most recent call last)",
            "\u001b[0;32m<ipython-input-14-012aba81a4be>\u001b[0m in \u001b[0;36m<module>\u001b[0;34m()\u001b[0m\n\u001b[1;32m     16\u001b[0m     \u001b[0mprint_message\u001b[0m\u001b[0;34m(\u001b[0m\u001b[0;34m\"Friday\"\u001b[0m\u001b[0;34m)\u001b[0m\u001b[0;34m\u001b[0m\u001b[0;34m\u001b[0m\u001b[0m\n\u001b[1;32m     17\u001b[0m \u001b[0;34m\u001b[0m\u001b[0m\n\u001b[0;32m---> 18\u001b[0;31m \u001b[0mprint_friday_message\u001b[0m\u001b[0;34m(\u001b[0m\u001b[0;34m)\u001b[0m\u001b[0;34m\u001b[0m\u001b[0;34m\u001b[0m\u001b[0m\n\u001b[0m",
            "\u001b[0;32m<ipython-input-14-012aba81a4be>\u001b[0m in \u001b[0;36mprint_friday_message\u001b[0;34m()\u001b[0m\n\u001b[1;32m     14\u001b[0m \u001b[0;34m\u001b[0m\u001b[0m\n\u001b[1;32m     15\u001b[0m \u001b[0;32mdef\u001b[0m \u001b[0mprint_friday_message\u001b[0m\u001b[0;34m(\u001b[0m\u001b[0;34m)\u001b[0m\u001b[0;34m:\u001b[0m\u001b[0;34m\u001b[0m\u001b[0;34m\u001b[0m\u001b[0m\n\u001b[0;32m---> 16\u001b[0;31m     \u001b[0mprint_message\u001b[0m\u001b[0;34m(\u001b[0m\u001b[0;34m\"Friday\"\u001b[0m\u001b[0;34m)\u001b[0m\u001b[0;34m\u001b[0m\u001b[0;34m\u001b[0m\u001b[0m\n\u001b[0m\u001b[1;32m     17\u001b[0m \u001b[0;34m\u001b[0m\u001b[0m\n\u001b[1;32m     18\u001b[0m \u001b[0mprint_friday_message\u001b[0m\u001b[0;34m(\u001b[0m\u001b[0;34m)\u001b[0m\u001b[0;34m\u001b[0m\u001b[0;34m\u001b[0m\u001b[0m\n",
            "\u001b[0;32m<ipython-input-14-012aba81a4be>\u001b[0m in \u001b[0;36mprint_message\u001b[0;34m(day)\u001b[0m\n\u001b[1;32m     11\u001b[0m         \u001b[0;34m\"sunday\"\u001b[0m\u001b[0;34m:\u001b[0m \u001b[0;34m\"Aw, the weekend is almost over.\"\u001b[0m\u001b[0;34m\u001b[0m\u001b[0;34m\u001b[0m\u001b[0m\n\u001b[1;32m     12\u001b[0m     }\n\u001b[0;32m---> 13\u001b[0;31m     \u001b[0mprint\u001b[0m\u001b[0;34m(\u001b[0m\u001b[0mmessages\u001b[0m\u001b[0;34m[\u001b[0m\u001b[0mday\u001b[0m\u001b[0;34m]\u001b[0m\u001b[0;34m)\u001b[0m\u001b[0;34m\u001b[0m\u001b[0;34m\u001b[0m\u001b[0m\n\u001b[0m\u001b[1;32m     14\u001b[0m \u001b[0;34m\u001b[0m\u001b[0m\n\u001b[1;32m     15\u001b[0m \u001b[0;32mdef\u001b[0m \u001b[0mprint_friday_message\u001b[0m\u001b[0;34m(\u001b[0m\u001b[0;34m)\u001b[0m\u001b[0;34m:\u001b[0m\u001b[0;34m\u001b[0m\u001b[0;34m\u001b[0m\u001b[0m\n",
            "\u001b[0;31mKeyError\u001b[0m: 'Friday'"
          ]
        }
      ]
    },
    {
      "cell_type": "markdown",
      "metadata": {
        "id": "a5IMyIsLseQM",
        "colab_type": "text"
      },
      "source": [
        "### Solution (side note)\n",
        "3 levels\n",
        "\n",
        "print_message\n",
        "\n",
        "11\n",
        "\n",
        "KeyError\n",
        "\n",
        "There isn’t really a message; you’re supposed to infer that \n",
        "\n",
        "Friday is not a key in messages."
      ]
    },
    {
      "cell_type": "markdown",
      "metadata": {
        "id": "sH5176_Ls7qO",
        "colab_type": "text"
      },
      "source": [
        "### Identifying Syntax Errors (side note)\n",
        "\n",
        "\n",
        "---\n",
        "\n",
        "\n",
        "1.   Read the code below, and (without running it) try to identify what the errors are.\n",
        "2.   Run the code, and read the error message. Is it a SyntaxError or an IndentationError?\n",
        "3.   Fix the error.\n",
        "4.   Repeat steps 2 and 3, until you have fixed all the errors.\n",
        "\n",
        "\n",
        "\n",
        "\n"
      ]
    },
    {
      "cell_type": "code",
      "metadata": {
        "id": "xHqF8DYbteSs",
        "colab_type": "code",
        "colab": {
          "base_uri": "https://localhost:8080/",
          "height": 130
        },
        "outputId": "9faea572-8ff4-4e28-cfc8-14b571f70af0"
      },
      "source": [
        "def another_function\n",
        "  print(\"Syntax errors are annoying.\")\n",
        "   print(\"But at least Python tells us about them!\")\n",
        "  print(\"So they are usually not too hard to fix.\")"
      ],
      "execution_count": 15,
      "outputs": [
        {
          "output_type": "error",
          "ename": "SyntaxError",
          "evalue": "ignored",
          "traceback": [
            "\u001b[0;36m  File \u001b[0;32m\"<ipython-input-15-c15a79c89afd>\"\u001b[0;36m, line \u001b[0;32m1\u001b[0m\n\u001b[0;31m    def another_function\u001b[0m\n\u001b[0m                        ^\u001b[0m\n\u001b[0;31mSyntaxError\u001b[0m\u001b[0;31m:\u001b[0m invalid syntax\n"
          ]
        }
      ]
    },
    {
      "cell_type": "markdown",
      "metadata": {
        "id": "4vIKnn8Eti6G",
        "colab_type": "text"
      },
      "source": [
        "### Solution (side note)\n",
        "SyntaxError for missing (): at end of first line, IndentationError for mismatch between second and third lines. A fixed version is:"
      ]
    },
    {
      "cell_type": "code",
      "metadata": {
        "id": "cBsdgo-EsiTi",
        "colab_type": "code",
        "colab": {}
      },
      "source": [
        "def another_function():\n",
        "    print(\"Syntax errors are annoying.\")\n",
        "    print(\"But at least Python tells us about them!\")\n",
        "    print(\"So they are usually not too hard to fix.\")"
      ],
      "execution_count": 0,
      "outputs": []
    },
    {
      "cell_type": "markdown",
      "metadata": {
        "id": "fq4dVtJgttIJ",
        "colab_type": "text"
      },
      "source": [
        "\n",
        "\n",
        "---\n"
      ]
    },
    {
      "cell_type": "markdown",
      "metadata": {
        "id": "arGKeNdzt1F_",
        "colab_type": "text"
      },
      "source": [
        "### Identifying Variable Name Errors (side note)\n",
        "\n",
        "\n",
        "---\n",
        "\n",
        "\n",
        "\n",
        "1.   Read the code below, and (without running it) try to identify what the errors are.\n",
        "2.   Run the code, and read the error message. What type of NameError do you think this is? In other words, is it a string with no quotes, a misspelled variable, or a variable that should have been defined but was not?\n",
        "3.   Fix the error.\n",
        "4.   Repeat steps 2 and 3, until you have fixed all the errors.\n",
        "\n"
      ]
    },
    {
      "cell_type": "code",
      "metadata": {
        "id": "Z1dvgiy2uMJQ",
        "colab_type": "code",
        "colab": {
          "base_uri": "https://localhost:8080/",
          "height": 232
        },
        "outputId": "adac14be-2746-4cfb-ded5-12950a55d322"
      },
      "source": [
        "for number in range(10):\n",
        "    # use a if the number is a multiple of 3, otherwise use b\n",
        "    if (Number % 3) == 0:\n",
        "        message = message + a\n",
        "    else:\n",
        "        message = message + \"b\"\n",
        "print(message)\n"
      ],
      "execution_count": 17,
      "outputs": [
        {
          "output_type": "error",
          "ename": "NameError",
          "evalue": "ignored",
          "traceback": [
            "\u001b[0;31m---------------------------------------------------------------------------\u001b[0m",
            "\u001b[0;31mNameError\u001b[0m                                 Traceback (most recent call last)",
            "\u001b[0;32m<ipython-input-17-f828fe325418>\u001b[0m in \u001b[0;36m<module>\u001b[0;34m()\u001b[0m\n\u001b[1;32m      1\u001b[0m \u001b[0;32mfor\u001b[0m \u001b[0mnumber\u001b[0m \u001b[0;32min\u001b[0m \u001b[0mrange\u001b[0m\u001b[0;34m(\u001b[0m\u001b[0;36m10\u001b[0m\u001b[0;34m)\u001b[0m\u001b[0;34m:\u001b[0m\u001b[0;34m\u001b[0m\u001b[0;34m\u001b[0m\u001b[0m\n\u001b[1;32m      2\u001b[0m     \u001b[0;31m# use a if the number is a multiple of 3, otherwise use b\u001b[0m\u001b[0;34m\u001b[0m\u001b[0;34m\u001b[0m\u001b[0;34m\u001b[0m\u001b[0m\n\u001b[0;32m----> 3\u001b[0;31m     \u001b[0;32mif\u001b[0m \u001b[0;34m(\u001b[0m\u001b[0mNumber\u001b[0m \u001b[0;34m%\u001b[0m \u001b[0;36m3\u001b[0m\u001b[0;34m)\u001b[0m \u001b[0;34m==\u001b[0m \u001b[0;36m0\u001b[0m\u001b[0;34m:\u001b[0m\u001b[0;34m\u001b[0m\u001b[0;34m\u001b[0m\u001b[0m\n\u001b[0m\u001b[1;32m      4\u001b[0m         \u001b[0mmessage\u001b[0m \u001b[0;34m=\u001b[0m \u001b[0mmessage\u001b[0m \u001b[0;34m+\u001b[0m \u001b[0ma\u001b[0m\u001b[0;34m\u001b[0m\u001b[0;34m\u001b[0m\u001b[0m\n\u001b[1;32m      5\u001b[0m     \u001b[0;32melse\u001b[0m\u001b[0;34m:\u001b[0m\u001b[0;34m\u001b[0m\u001b[0;34m\u001b[0m\u001b[0m\n",
            "\u001b[0;31mNameError\u001b[0m: name 'Number' is not defined"
          ]
        }
      ]
    },
    {
      "cell_type": "markdown",
      "metadata": {
        "id": "_ms31Ko0uSrO",
        "colab_type": "text"
      },
      "source": [
        "NameErrors for number being misspelled, for message not defined, and for a not being in quotes.\n",
        "\n",
        "Fixed version:"
      ]
    },
    {
      "cell_type": "code",
      "metadata": {
        "id": "vCc6LN2ntsV-",
        "colab_type": "code",
        "colab": {
          "base_uri": "https://localhost:8080/",
          "height": 34
        },
        "outputId": "ae400387-d360-4011-8709-faf71ddce55a"
      },
      "source": [
        "message = \"\"\n",
        "for number in range(10):\n",
        "    # use a if the number is a multiple of 3, otherwise use b\n",
        "    if (number % 3) == 0:\n",
        "        message = message + \"a\"\n",
        "    else:\n",
        "        message = message + \"b\"\n",
        "print(message)"
      ],
      "execution_count": 18,
      "outputs": [
        {
          "output_type": "stream",
          "text": [
            "abbabbabba\n"
          ],
          "name": "stdout"
        }
      ]
    },
    {
      "cell_type": "markdown",
      "metadata": {
        "id": "6XM-Ku6tuZZ0",
        "colab_type": "text"
      },
      "source": [
        "\n",
        "\n",
        "---\n",
        "\n"
      ]
    },
    {
      "cell_type": "markdown",
      "metadata": {
        "id": "gCsnGVzLueJq",
        "colab_type": "text"
      },
      "source": [
        "### Identifying Index Errors (side note)\n",
        "\n",
        "\n",
        "---\n",
        "\n",
        "\n",
        "\n",
        "1.   Read the code below, and (without running it) try to identify what the errors are.\n",
        "2.   Run the code, and read the error message. What type of error is it?\n",
        "3.   Fix the error.\n",
        "\n"
      ]
    },
    {
      "cell_type": "code",
      "metadata": {
        "id": "J_vNvaQGuYLc",
        "colab_type": "code",
        "colab": {
          "base_uri": "https://localhost:8080/",
          "height": 181
        },
        "outputId": "360a054f-790a-4bc2-a1dd-8c7801eafa32"
      },
      "source": [
        "seasons = ['Spring', 'Summer', 'Fall', 'Winter']\n",
        "print('My favorite season is ', seasons[4])"
      ],
      "execution_count": 19,
      "outputs": [
        {
          "output_type": "error",
          "ename": "IndexError",
          "evalue": "ignored",
          "traceback": [
            "\u001b[0;31m---------------------------------------------------------------------------\u001b[0m",
            "\u001b[0;31mIndexError\u001b[0m                                Traceback (most recent call last)",
            "\u001b[0;32m<ipython-input-19-c82c08095380>\u001b[0m in \u001b[0;36m<module>\u001b[0;34m()\u001b[0m\n\u001b[1;32m      1\u001b[0m \u001b[0mseasons\u001b[0m \u001b[0;34m=\u001b[0m \u001b[0;34m[\u001b[0m\u001b[0;34m'Spring'\u001b[0m\u001b[0;34m,\u001b[0m \u001b[0;34m'Summer'\u001b[0m\u001b[0;34m,\u001b[0m \u001b[0;34m'Fall'\u001b[0m\u001b[0;34m,\u001b[0m \u001b[0;34m'Winter'\u001b[0m\u001b[0;34m]\u001b[0m\u001b[0;34m\u001b[0m\u001b[0;34m\u001b[0m\u001b[0m\n\u001b[0;32m----> 2\u001b[0;31m \u001b[0mprint\u001b[0m\u001b[0;34m(\u001b[0m\u001b[0;34m'My favorite season is '\u001b[0m\u001b[0;34m,\u001b[0m \u001b[0mseasons\u001b[0m\u001b[0;34m[\u001b[0m\u001b[0;36m4\u001b[0m\u001b[0;34m]\u001b[0m\u001b[0;34m)\u001b[0m\u001b[0;34m\u001b[0m\u001b[0;34m\u001b[0m\u001b[0m\n\u001b[0m",
            "\u001b[0;31mIndexError\u001b[0m: list index out of range"
          ]
        }
      ]
    },
    {
      "cell_type": "markdown",
      "metadata": {
        "id": "ckE2_3qpuwdX",
        "colab_type": "text"
      },
      "source": [
        "IndexError; the last entry is seasons[3], so seasons[4] doesn’t make sense. A fixed version is:"
      ]
    },
    {
      "cell_type": "code",
      "metadata": {
        "id": "44OkfP_4uvov",
        "colab_type": "code",
        "colab": {
          "base_uri": "https://localhost:8080/",
          "height": 34
        },
        "outputId": "42b07009-96f3-4768-fa43-30d4f207ba39"
      },
      "source": [
        "seasons = ['Spring', 'Summer', 'Fall', 'Winter']\n",
        "print('My favorite season is ', seasons[-1])"
      ],
      "execution_count": 20,
      "outputs": [
        {
          "output_type": "stream",
          "text": [
            "My favorite season is  Winter\n"
          ],
          "name": "stdout"
        }
      ]
    },
    {
      "cell_type": "markdown",
      "metadata": {
        "id": "WzNs0XBdu6zM",
        "colab_type": "text"
      },
      "source": [
        "\n",
        "\n",
        "---\n",
        "\n"
      ]
    },
    {
      "cell_type": "markdown",
      "metadata": {
        "id": "xrCO54t_u_IU",
        "colab_type": "text"
      },
      "source": [
        "## Key points\n",
        "*  Tracebacks can look intimidating, but they give us a lot of useful information about what went wrong in our program, including where the error occurred and what type of error it was.\n",
        "\n",
        "*  An error having to do with the ‘grammar’ or syntax of the program is called a SyntaxError. If the issue has to do with how the code is indented, then it will be called an IndentationError.\n",
        "\n",
        "*  A NameError will occur when trying to use a variable that does not exist. Possible causes are that a variable definition is missing, a variable reference differs from its definition in spelling or capitalization, or the code contains a string that is missing quotes around it.\n",
        "\n",
        "*  Containers like lists and strings will generate errors if you try to access items in them that do not exist. This type of error is called an IndexError.\n",
        "\n",
        "*  Trying to read a file that does not exist will give you an FileNotFoundError. Trying to read a file that is open for writing, or writing to a file that is open for reading, will give you an IOError.\n",
        "\n",
        "\n"
      ]
    }
  ]
}